Workbook

Sheet Monthly Bills
A1: MONTHLY BILLS - EDIT HERE
A2: (Yellow cells are editable - changes update all tabs)
A4: CURRENT INCOME | D4: CATEGORY SUMMARY
A5: Source | B5: Amount | D5: Category | E5: Amount
A6: Your Income (monthly) | B6: 6000 | D6: Vehicles | E6: =B34 -> 0
A7: Wife's Income (monthly) | B7: 4875.5 | D7: Housing | E7: =B41 -> 0
A8: TOTAL CURRENT INCOME | B8: =SUM(B6:B7) -> 0 | D8: Utilities | E8: =B50 -> 0
D9: Insurance | E9: =B56 -> 0
A10: PROJECTED INCOME (After Wife's Raise) | D10: Debt Payments | E10: =B64 -> 0
A11: Source | B11: Amount | D11: Subscriptions | E11: =B72 -> 0
A12: Your Income | B12: =B6 -> 0 | D12: Other | E12: =B79 -> 0
A13: Wife's Projected Income | B13: 5875
A14: TOTAL PROJECTED INCOME | B14: =SUM(B12:B13) -> 0
A15: PROJECTED INCREASE | B15: =B14-B8 -> 0
A17: SETTINGS
A18: Bills Account Buffer | B18: 200
A19: Monthly Savings Goal | B19: 900
A21: DIRECT DEPOSIT (Auto-deducted from paycheck)
A22: Description | B22: Per Paycheck
A23: Your DD (Boat & Small Loan) | B23: 450
A24: Wife's DD (if any) | B24: 0
A25: Your Monthly DD Total | B25: =B23*2 -> 0
A26: Wife's Monthly DD Total | B26: =B24*2.167 -> 0
A28: VEHICLES
A29: Expense | B29: Amount
A30: Truck Payment | B30: 900
A31: Car Payment | B31: 700
A32: Boat (via Direct Deposit) | B32: 565
A33: Fuel | B33: 800
A34: Vehicles Total | B34: =SUM(B30:B33) -> 0
A36: HOUSING
A37: Expense | B37: Amount
A38: Shelter 1 | B38: 641
A39: Shelter 2 | B39: 362.9
A40: Shelter 3 | B40: 300
A41: Housing Total | B41: =SUM(B38:B40) -> 0
A43: UTILITIES
A44: Expense | B44: Amount
A45: Power | B45: 400
A46: Internet | B46: 85
...

Sheet Paycheck Breakdown
A1: PAYCHECK BREAKDOWN - WHERE TO PUT YOUR MONEY
A2: (Shows exactly how much from each paycheck goes to each account)
A4: MONTHLY TARGETS (what we need total each month)
B5: Total Monthly | C5: Bills Account | D5: Savings Account | E5: Spending Account
A6: Monthly Target | B6: ='Monthly Bills'!B8 -> 0 | C6: ='Monthly Bills'!B84+'Monthly Bills'!B18 -> 0 | D6: ='Monthly Bills'!B19 -> 0 | E6: =B6-C6-D6-'Monthly Bills'!B25-'Monthly Bills'!B26 -> 0
A8: YOUR PAYCHECKS (15th & Last Day of Month) - 2 per month
B9: Amount | C9: Bills Account | D9: Savings Account | E9: Spending Account
A10: Your Gross Paycheck | B10: ='Monthly Bills'!B6/2 -> 0
A11: MINUS: Direct Deposit (Boat & Loan) | B11: =-'Monthly Bills'!B23 -> 0
A12: Your Take-Home to Split | B12: =B10+B11 -> 0
A13: Each Paycheck - Put in: | B13: =B12 -> 0 | C13: =ROUND(('Monthly Bills'!B6/'Monthly Bills'!B8)*$C$6/2,2) -> 0 | D13: =ROUND(('Monthly Bills'!B6/'Monthly Bills'!B8)*$D$6/2,2) -> 0 | E13: =B13-C13-D13 -> 0
A14: YOUR MONTHLY TOTAL | B14: =B13*2 -> 0 | C14: =C13*2 -> 0 | D14: =D13*2 -> 0 | E14: =E13*2 -> 0
A15: (Plus Direct Deposit pays bills) | B15: ='Monthly Bills'!B25 -> 0
A17: WIFE'S PAYCHECKS (Every 2 Weeks) - avg 2.167 per month
B18: Amount | C18: Bills Account | D18: Savings Account | E18: Spending Account
A19: Wife's Gross Paycheck | B19: ='Monthly Bills'!B7/2.167 -> 0
A20: MINUS: Direct Deposit (if any) | B20: =-'Monthly Bills'!B24 -> 0
A21: Wife's Take-Home to Split | B21: =B19+B20 -> 0
A22: Each Paycheck - Put in: | B22: =B21 -> 0 | C22: =ROUND(('Monthly Bills'!B7/'Monthly Bills'!B8)*$C$6/2.167,2) -> 0 | D22: =ROUND(('Monthly Bills'!B7/'Monthly Bills'!B8)*$D$6/2.167,2) -> 0 | E22: =B22-C22-D22 -> 0
A23: WIFE'S MONTHLY TOTAL (avg) | B23: =B22*2.167 -> 0 | C23: =C22*2.167 -> 0 | D23: =D22*2.167 -> 0 | E23: =E22*2.167 -> 0
A24: (Plus Direct Deposit pays bills) | B24: ='Monthly Bills'!B26 -> 0
A26: COMBINED MONTHLY TOTALS (You + Wife)
B27: Total Income | C27: Bills Account | D27: Savings Account | E27: Spending Account
A28: From Paychecks to Accounts | B28: =B14+B23 -> 0 | C28: =C14+C23 -> 0 | D28: =D14+D23 -> 0 | E28: =E14+E23 -> 0
A29: Direct Deposits (pay bills directly) | B29: =B15+B24 -> 0 | C29: (pays bills)
A30: GRAND TOTAL | B30: =B28+B29 -> 0 | C30: =C28 -> 0 | D30: =D28 -> 0 | E30: =E28 -> 0
A31: Target (should match) | B31: =B6 -> 0 | C31: =C6 -> 0 | D31: =D6 -> 0 | E31: =E6 -> 0
A33: QUICK REFERENCE - COPY THIS TO YOUR PHONE!
A35: YOUR PAYCHECKS (15th & Last Day) | D35: WIFE'S PAYCHECKS (Every 2 Weeks)
A36: Gross Paycheck: | B36: =B10 -> 0 | D36: Gross Paycheck: | E36: =B19 -> 0
A37: Direct Deposit (auto): | B37: ='Monthly Bills'!B23 -> 0 | D37: Direct Deposit (auto): | E37: ='Monthly Bills'!B24 -> 0
A38: Take-Home to Split: | B38: =B12 -> 0 | D38: Take-Home to Split: | E38: =B21 -> 0
A39: → Bills Account: | B39: =C13 -> 0 | D39: → Bills Account: | E39: =C22 -> 0
A40: → Savings Account: | B40: =D13 -> 0 | D40: → Savings Account: | E40: =D22 -> 0
A41: → Spending Account: | B41: =E13 -> 0 | D41: → Spending Account: | E41: =E22 -> 0
A43: NOTE: Your $450 direct deposit automatically pays Boat & Small Loan - already accounted for in bills!
A44: Wife gets 3 paychecks some months (2 extra/year). Use those for extra savings or debt payoff!

Sheet Overview
A1: BUDGET OVERVIEW
A2: (All values linked to Monthly Bills tab)
A4: CURRENT INCOME | D4: CURRENT ACCOUNT ALLOCATION
A5: Source | B5: Amount | D5: Account | E5: Amount
A6: Your Income | B6: ='Monthly Bills'!B6 -> 0 | D6: Bills Account | E6: ='Monthly Bills'!B84+'Monthly Bills'!B18 -> 0
A7: Wife's Income | B7: ='Monthly Bills'!B7 -> 0 | D7: Savings Account | E7: ='Monthly Bills'!B19 -> 0
A8: TOTAL INCOME | B8: ='Monthly Bills'!B8 -> 0 | D8: Spending Account | E8: ='Monthly Bills'!B8-E6-E7-'Monthly Bills'!B25-'Monthly Bills'!B26 -> 0
D9: Direct Deposits (auto) | E9: ='Monthly Bills'!B25+'Monthly Bills'!B26 -> 0
A10: CURRENT MONTHLY SUMMARY | D10: TOTAL | E10: =SUM(E6:E9) -> 0
A11: Total Income | B11: ='Monthly Bills'!B8 -> 0
A12: Total Expenses | B12: ='Monthly Bills'!B82 -> 0
A13: Bills Buffer | B13: ='Monthly Bills'!B18 -> 0
A14: Savings | B14: ='Monthly Bills'!B19 -> 0
A15: Spending Money | B15: =E8 -> 0
A17: PROJECTED INCOME (After Raise) | D17: PROJECTED ACCOUNT ALLOCATION
A18: Source | B18: Amount | D18: Account | E18: Amount
A19: Your Income | B19: ='Monthly Bills'!B12 -> 0 | D19: Bills Account | E19: ='Monthly Bills'!B84+'Monthly Bills'!B18 -> 0
A20: Wife's Projected Income | B20: ='Monthly Bills'!B13 -> 0 | D20: Savings Account | E20: ='Monthly Bills'!B19 -> 0
A21: TOTAL PROJECTED INCOME | B21: ='Monthly Bills'!B14 -> 0 | D21: Spending Account | E21: ='Monthly Bills'!B14-E19-E20-'Monthly Bills'!B25-'Monthly Bills'!B26 -> 0
D22: Direct Deposits (auto) | E22: ='Monthly Bills'!B25+'Monthly Bills'!B26 -> 0
A23: PROJECTED MONTHLY SUMMARY | D23: TOTAL | E23: =SUM(E19:E22) -> 0
A24: Total Projected Income | B24: ='Monthly Bills'!B14 -> 0
A25: Total Expenses | B25: ='Monthly Bills'!B82 -> 0
A26: Bills Buffer | B26: ='Monthly Bills'!B18 -> 0
A27: Savings | B27: ='Monthly Bills'!B19 -> 0
A28: Projected Spending Money | B28: =E21 -> 0
A29: EXTRA vs CURRENT | B29: =B28-B15 -> 0

Sheet Spending Budget
A1: SPENDING ACCOUNT BUDGET
A3: CURRENT SPENDING BUDGET | E3: PROJECTED SPENDING BUDGET
A4: Available for Spending: | B4: =Overview!E8 -> 0 | E4: Projected Available: | F4: =Overview!E21 -> 0
A6: Category | B6: Budget | C6: % of Total | E6: Category | F6: Budget | G6: % of Total
A7: Dining Out/Entertainment | B7: 350 | C7: =IF($B$4>0,B7/$B$4,0) -> 0 | E7: Dining Out/Entertainment | F7: =B7 -> 0 | G7: =IF($F$4>0,F7/$F$4,0) -> 0
A8: Personal (You) | B8: 225 | C8: =IF($B$4>0,B8/$B$4,0) -> 0 | E8: Personal (You) | F8: =B8 -> 0 | G8: =IF($F$4>0,F8/$F$4,0) -> 0
A9: Personal (Wife) | B9: 225 | C9: =IF($B$4>0,B9/$B$4,0) -> 0 | E9: Personal (Wife) | F9: =B9 -> 0 | G9: =IF($F$4>0,F9/$F$4,0) -> 0
A10: Household Items | B10: 175 | C10: =IF($B$4>0,B10/$B$4,0) -> 0 | E10: Household Items | F10: =B10 -> 0 | G10: =IF($F$4>0,F10/$F$4,0) -> 0
A11: Car Maintenance | B11: 150 | C11: =IF($B$4>0,B11/$B$4,0) -> 0 | E11: Car Maintenance | F11: =B11 -> 0 | G11: =IF($F$4>0,F11/$F$4,0) -> 0
A12: Medical/Health | B12: 150 | C12: =IF($B$4>0,B12/$B$4,0) -> 0 | E12: Medical/Health | F12: =B12 -> 0 | G12: =IF($F$4>0,F12/$F$4,0) -> 0
A13: Clothing | B13: 100 | C13: =IF($B$4>0,B13/$B$4,0) -> 0 | E13: Clothing | F13: =B13 -> 0 | G13: =IF($F$4>0,F13/$F$4,0) -> 0
A14: Miscellaneous/Buffer | B14: =$B$4-SUM(B7:B13) -> 0 | C14: =IF($B$4>0,B14/$B$4,0) -> 0 | E14: Miscellaneous/Buffer | F14: =$F$4-SUM(F7:F13) -> 0 | G14: =IF($F$4>0,F14/$F$4,0) -> 0
A16: TOTAL BUDGETED | B16: =SUM(B7:B14) -> 0 | E16: TOTAL BUDGETED | F16: =SUM(F7:F14) -> 0
E18: EXTRA BUFFER vs CURRENT | F18: =F14-B14 -> 0
